Workbook

Sheet Compare2024to2014
A5: This Worksheet compares model results with 2024 and 2014 energy prices
A7: Compare Hydropeaking value at 0 days of steady low flows for 2024 and 2014 prices ($ million)
B10: ='Table1-2024Prices'!B40 -> Month | C10: 2024 | D10: 2014 | E10: Difference | F10: Comment
B11: ='Table1-2024Prices'!B41 -> March | C11: ='Table1-2024Prices'!C41 -> 17.85 | D11: ='Table1-2014Prices'!C29 -> 19.9 | E11: =C11-D11 -> -2.05 | F11: Tradeoff curve shifted right to higher hydropeaking value when moved from 2024 to 2014 prices
B12: ='Table1-2024Prices'!B42 -> April | C12: ='Table1-2024Prices'!C42 -> 17.44 | D12: ='Table1-2014Prices'!C30 -> 18.2 | E12: =C12-D12 -> -0.76 | F12: Tradeoff curve shifted right to higher hydropeaking value when moved from 2024 to 2014 prices
B13: ='Table1-2024Prices'!B43 -> May | C13: ='Table1-2024Prices'!C43 -> 15.57 | D13: ='Table1-2014Prices'!C31 -> 18.4 | E13: =C13-D13 -> -2.83 | F13: Tradeoff curve shifted right to higher hydropeaking value when moved from 2024 to 2014 prices
B14: ='Table1-2024Prices'!B44 -> June | C14: ='Table1-2024Prices'!C44 -> 19.58 | D14: ='Table1-2014Prices'!C32 -> 20.1 | E14: =C14-D14 -> -0.52 | F14: Tradeoff curve shifted right to higher hydropeaking value when moved from 2024 to 2014 prices
B15: ='Table1-2024Prices'!B45 -> July | C15: ='Table1-2024Prices'!C45 -> 28.9 | D15: ='Table1-2014Prices'!C33 -> 25.3 | E15: =C15-D15 -> 3.6 | F15: Tradeoff curve shifted left to lower hydropeaking value when moved from 2024 to 2014 prices
B16: ='Table1-2024Prices'!B46 -> August | C16: ='Table1-2024Prices'!C46 -> 34.36 | D16: ='Table1-2014Prices'!C34 -> 25.5 | E16: =C16-D16 -> 8.86
B17: ='Table1-2024Prices'!B47 -> September | C17: ='Table1-2024Prices'!C47 -> 28.62 | D17: ='Table1-2014Prices'!C35 -> 23.6 | E17: =C17-D17 -> 5.02
B18: ='Table1-2024Prices'!B48 -> October | C18: ='Table1-2024Prices'!C48 -> 24.72 | D18: ='Table1-2014Prices'!C36 -> 21.8 | E18: =C18-D18 -> 2.92
B19: Total | C19: =SUM(C11:C18) -> 187.04 | D19: =SUM(D11:D18) -> 172.8 | E19: =SUM(E11:E18) -> 14.24
A22: Difference in cummulative losses (2024 minus 2014 ) ($ million)
C23: Number of Days of Steady Low Releases
B24: ='Table1-2024Prices'!B40 -> Month | C24: ='Table1-2024Prices'!C40 -> 0 | D24: ='Table1-2024Prices'!D40 -> 4 | E24: ='Table1-2024Prices'!E40 -> 6 | F24: ='Table1-2024Prices'!F40 -> 8 | G24: ='Table1-2024Prices'!G40 -> 10 | H24: ='Table1-2024Prices'!H40 -> 15 | I24: ='Table1-2024Prices'!I40 -> 20 | ... L24: ='Table1-2024Prices'!L40 -> 31 | M24: Comment
B25: ='Table1-2024Prices'!B41 -> March | C25: ='Table1-2024Prices'!C41-'Table1-2014Prices'!C29 -> -2.05 | D25: ='Table1-2024Prices'!D41-'Table1-2014Prices'!D29 -> 0.13362184 | E25: ='Table1-2024Prices'!E41-'Table1-2014Prices'!E29 -> 0.14625812 | F25: ='Table1-2024Prices'!F41-'Table1-2014Prices'!F29 -> 0.15630986 | G25: ='Table1-2024Prices'!G41-'Table1-2014Prices'!G29 -> 0.14380728 | H25: ='Table1-2024Prices'!H41-'Table1-2014Prices'!H29 -> 0.11666501 | I25: ='Table1-2024Prices'!I41-'Table1-2014Prices'!I29 -> 0.10369119 | J25: ='Table1-2024Prices'!J41-'Table1-2014Prices'!J29 -> 0.083712325 | L25: ='Table1-2024Prices'!L41-'Table1-2014Prices'!L29 -> 0.07 | M25: A negative cummulative loss means 2014 loss was higher than 2024 loss
B26: ='Table1-2024Prices'!B42 -> April | C26: ='Table1-2024Prices'!C42-'Table1-2014Prices'!C30 -> -0.76 | D26: ='Table1-2024Prices'!D42-'Table1-2014Prices'!D30 -> 0.24226369 | E26: ='Table1-2024Prices'!E42-'Table1-2014Prices'!E30 -> 0.26044578 | F26: ='Table1-2024Prices'!F42-'Table1-2014Prices'!F30 -> 0.28114302 | G26: ='Table1-2024Prices'!G42-'Table1-2014Prices'!G30 -> 0.28761274 | H26: ='Table1-2024Prices'!H42-'Table1-2014Prices'!H30 -> 0.34127473 | I26: ='Table1-2024Prices'!I42-'Table1-2014Prices'!I30 -> 0.35207556 | J26: ='Table1-2024Prices'!J42-'Table1-2014Prices'!J30 -> 0.3584802 | K26: ='Table1-2024Prices'!K42-'Table1-2014Prices'!K30 -> 0.3686207 | M26: A negative cummulative loss means 2014 loss was higher than 2024 loss
B27: ='Table1-2024Prices'!B43 -> May | C27: ='Table1-2024Prices'!C43-'Table1-2014Prices'!C31 -> -2.83 | D27: ='Table1-2024Prices'!D43-'Table1-2014Prices'!D31 -> 0.25701891 | E27: ='Table1-2024Prices'!E43-'Table1-2014Prices'!E31 -> 0.29478991 | F27: ='Table1-2024Prices'!F43-'Table1-2014Prices'!F31 -> 0.30760772 | G27: ='Table1-2024Prices'!G43-'Table1-2014Prices'!G31 -> 0.28797087 | H27: ='Table1-2024Prices'!H43-'Table1-2014Prices'!H31 -> 0.28030148 | I27: ='Table1-2024Prices'!I43-'Table1-2014Prices'!I31 -> 0.28978791 | J27: ='Table1-2024Prices'!J43-'Table1-2014Prices'!J31 -> 0.23706954 | L27: ='Table1-2024Prices'!L43-'Table1-2014Prices'!L31 -> 0.22 | M27: A negative cummulative loss means 2014 loss was higher than 2024 loss
B28: ='Table1-2024Prices'!B44 -> June | C28: ='Table1-2024Prices'!C44-'Table1-2014Prices'!C32 -> -0.52 | D28: ='Table1-2024Prices'!D44-'Table1-2014Prices'!D32 -> 0.20296322 | E28: ='Table1-2024Prices'!E44-'Table1-2014Prices'!E32 -> 0.21907758 | F28: ='Table1-2024Prices'!F44-'Table1-2014Prices'!F32 -> 0.24908064 | G28: ='Table1-2024Prices'!G44-'Table1-2014Prices'!G32 -> 0.22366152 | H28: ='Table1-2024Prices'!H44-'Table1-2014Prices'!H32 -> 0.16177804 | I28: ='Table1-2024Prices'!I44-'Table1-2014Prices'!I32 -> 0.15031817 | J28: ='Table1-2024Prices'!J44-'Table1-2014Prices'!J32 -> 0.13539685 | K28: ='Table1-2024Prices'!K44-'Table1-2014Prices'!K32 -> 0.11984488 | M28: A negative cummulative loss means 2014 loss was higher than 2024 loss
B29: ='Table1-2024Prices'!B45 -> July | C29: ='Table1-2024Prices'!C45-'Table1-2014Prices'!C33 -> 3.6 | D29: ='Table1-2024Prices'!D45-'Table1-2014Prices'!D33 -> 0.12082173 | E29: ='Table1-2024Prices'!E45-'Table1-2014Prices'!E33 -> 0.15960752 | F29: ='Table1-2024Prices'!F45-'Table1-2014Prices'!F33 -> 0.17198282 | G29: ='Table1-2024Prices'!G45-'Table1-2014Prices'!G33 -> 0.13199996 | H29: ='Table1-2024Prices'!H45-'Table1-2014Prices'!H33 -> 0.071536588 | I29: ='Table1-2024Prices'!I45-'Table1-2014Prices'!I33 -> 0.041718222 | J29: ='Table1-2024Prices'!J45-'Table1-2014Prices'!J33 -> 0.026095881 | L29: ='Table1-2024Prices'!L45-'Table1-2014Prices'!L33 -> 0.01
B30: ='Table1-2024Prices'!B46 -> August | C30: ='Table1-2024Prices'!C46-'Table1-2014Prices'!C34 -> 8.86 | D30: ='Table1-2024Prices'!D46-'Table1-2014Prices'!D34 -> 0.26025466 | E30: ='Table1-2024Prices'!E46-'Table1-2014Prices'!E34 -> 0.28806962 | F30: ='Table1-2024Prices'!F46-'Table1-2014Prices'!F34 -> 0.30903881 | G30: ='Table1-2024Prices'!G46-'Table1-2014Prices'!G34 -> 0.37548206 | H30: ='Table1-2024Prices'!H46-'Table1-2014Prices'!H34 -> 0.54676767 | I30: ='Table1-2024Prices'!I46-'Table1-2014Prices'!I34 -> 0.69232901 | J30: ='Table1-2024Prices'!J46-'Table1-2014Prices'!J34 -> 0.80776809 | L30: ='Table1-2024Prices'!L46-'Table1-2014Prices'!L34 -> 0.93
B31: ='Table1-2024Prices'!B47 -> September | C31: ='Table1-2024Prices'!C47-'Table1-2014Prices'!C35 -> 5.02 | D31: ='Table1-2024Prices'!D47-'Table1-2014Prices'!D35 -> 0.41737542 | E31: ='Table1-2024Prices'!E47-'Table1-2014Prices'!E35 -> 0.43617207 | F31: ='Table1-2024Prices'!F47-'Table1-2014Prices'!F35 -> 0.44628341 | G31: ='Table1-2024Prices'!G47-'Table1-2014Prices'!G35 -> 0.57459394 | H31: ='Table1-2024Prices'!H47-'Table1-2014Prices'!H35 -> 0.89355913 | I31: ='Table1-2024Prices'!I47-'Table1-2014Prices'!I35 -> 1.0184753 | J31: ='Table1-2024Prices'!J47-'Table1-2014Prices'!J35 -> 1.1370336 | K31: ='Table1-2024Prices'!K47-'Table1-2014Prices'!K35 -> 1.2346866
B32: ='Table1-2024Prices'!B48 -> October | C32: ='Table1-2024Prices'!C48-'Table1-2014Prices'!C36 -> 2.92 | D32: ='Table1-2024Prices'!D48-'Table1-2014Prices'!D36 -> 0.20876744 | E32: ='Table1-2024Prices'!E48-'Table1-2014Prices'!E36 -> 0.23605942 | F32: ='Table1-2024Prices'!F48-'Table1-2014Prices'!F36 -> 0.25125878 | G32: ='Table1-2024Prices'!G48-'Table1-2014Prices'!G36 -> 0.26121329 | H32: ='Table1-2024Prices'!H48-'Table1-2014Prices'!H36 -> 0.32407236 | I32: ='Table1-2024Prices'!I48-'Table1-2014Prices'!I36 -> 0.36400553 | J32: ='Table1-2024Prices'!J48-'Table1-2014Prices'!J36 -> 0.39474565 | L32: ='Table1-2024Prices'!L48-'Table1-2014Prices'!L36 -> 0.44
A36: Table S8. Change in hydropeaking value ($1000) per additional steady low flow day added in 2018 with 0.83 MAF release volume, H1000 (offset release), and contract energy price. Positive values show an increase; negative values a decrease.
B38: ='Table1-2024Prices'!A55 -> Month | C38: 2024 Energy Prices | F38: 2014 Energy Prices
C39: ='Table1-2024Prices'!B55 -> 0 and 4 steady low flow days | D39: ='Table1-2024Prices'!C55 -> 4 to 8 steady low flow days | E39: ='Table1-2024Prices'!D55 -> Above 8 steady low flow days | F39: =C39 -> 0 and 4 steady low flow days | G39: =D39 -> 4 to 8 steady low flow days | H39: =E39 -> Above 8 steady low flow days
B40: ='Table1-2024Prices'!A56 -> March | C40: ='Table1-2024Prices'!B56 -> -7 | D40: ='Table1-2024Prices'!C56 -> -7 | E40: ='Table1-2024Prices'!D56 -> -32 | F40: ='Table1-2014Prices'!C42 -> 20 | G40: ='Table1-2014Prices'!D42 -> -0.6 | H40: ='Table1-2014Prices'!E42 -> -30
B41: ='Table1-2024Prices'!A57 -> April | C41: ='Table1-2024Prices'!B57 -> -14 | D41: ='Table1-2024Prices'!C57 -> -14 | E41: ='Table1-2024Prices'!D57 -> -43 | F41: ='Table1-2014Prices'!C43 -> 23 | G41: ='Table1-2014Prices'!D43 -> -1.2 | H41: ='Table1-2014Prices'!E43 -> -43
B42: ='Table1-2024Prices'!A58 -> May | C42: ='Table1-2024Prices'!B58 -> -18 | D42: ='Table1-2024Prices'!C58 -> -18 | E42: ='Table1-2024Prices'!D58 -> -50 | F42: ='Table1-2014Prices'!C44 -> 30 | G42: ='Table1-2014Prices'!D44 -> -1 | H42: ='Table1-2014Prices'!E44 -> -44
B43: ='Table1-2024Prices'!A59 -> June | C43: ='Table1-2024Prices'!B59 -> -15 | D43: ='Table1-2024Prices'!C59 -> -15 | E43: ='Table1-2024Prices'!D59 -> -50 | F43: ='Table1-2014Prices'!C45 -> 37 | G43: ='Table1-2014Prices'!D45 -> -1.5 | H43: ='Table1-2014Prices'!E45 -> -54
B44: ='Table1-2024Prices'!A60 -> July | C44: ='Table1-2024Prices'!B60 -> -19 | D44: ='Table1-2024Prices'!C60 -> -19 | E44: ='Table1-2024Prices'!D60 -> -50 | F44: ='Table1-2014Prices'!C46 -> 48 | G44: ='Table1-2014Prices'!D46 -> -1.6 | H44: ='Table1-2014Prices'!E46 -> -70
B45: ='Table1-2024Prices'!A61 -> August | C45: ='Table1-2024Prices'!B61 -> 10 | D45: ='Table1-2024Prices'!C61 -> 10 | E45: ='Table1-2024Prices'!D61 -> -73 | F45: ='Table1-2014Prices'!C47 -> 42 | G45: ='Table1-2014Prices'!D47 -> -1.4 | H45: ='Table1-2014Prices'!E47 -> -61
B46: ='Table1-2024Prices'!A62 -> September | C46: ='Table1-2024Prices'!B62 -> 2 | D46: ='Table1-2024Prices'!C62 -> 2 | E46: ='Table1-2024Prices'!D62 -> -76 | F46: ='Table1-2014Prices'!C48 -> 25 | G46: ='Table1-2014Prices'!D48 -> -1 | H46: ='Table1-2014Prices'!E48 -> -37
B47: ='Table1-2024Prices'!A63 -> October | C47: ='Table1-2024Prices'!B63 -> -8 | D47: ='Table1-2024Prices'!C63 -> -8 | E47: ='Table1-2024Prices'!D63 -> -42 | F47: ='Table1-2014Prices'!C49 -> 26 | G47: ='Table1-2014Prices'!D49 -> -0.8 | H47: ='Table1-2014Prices'!E49 -> -38
A50: Difference in hydropeaking value ($1000) from 2024 to 2014 energy prices per additional steady low flow day added in 2018 with 0.83 MAF release volume, H1000 (offset release), and contract energy price. Positive values indicate 2024 value is higher than 2014 value..
A52: ='Table1-2024Prices'!A55 -> Month | B52: ='Table1-2024Prices'!B55 -> 0 and 4 steady low flow days | C52: ='Table1-2024Prices'!C55 -> 4 to 8 steady low flow days | D52: ='Table1-2024Prices'!D55 -> Above 8 steady low flow days
A53: ='Table1-2024Prices'!A56 -> March | B53: ='Table1-2024Prices'!B56-'Table1-2014Prices'!C42 -> -27 | C53: ='Table1-2024Prices'!C56-'Table1-2014Prices'!D42 -> -6.4 | D53: ='Table1-2024Prices'!D56-'Table1-2014Prices'!E42 -> -2
A54: ='Table1-2024Prices'!A57 -> April | B54: ='Table1-2024Prices'!B57-'Table1-2014Prices'!C43 -> -37 | C54: ='Table1-2024Prices'!C57-'Table1-2014Prices'!D43 -> -12.8 | D54: ='Table1-2024Prices'!D57-'Table1-2014Prices'!E43 -> 0
A55: ='Table1-2024Prices'!A58 -> May | B55: ='Table1-2024Prices'!B58-'Table1-2014Prices'!C44 -> -48 | C55: ='Table1-2024Prices'!C58-'Table1-2014Prices'!D44 -> -17 | D55: ='Table1-2024Prices'!D58-'Table1-2014Prices'!E44 -> -6
A56: ='Table1-2024Prices'!A59 -> June | B56: ='Table1-2024Prices'!B59-'Table1-2014Prices'!C45 -> -52 | C56: ='Table1-2024Prices'!C59-'Table1-2014Prices'!D45 -> -13.5 | D56: ='Table1-2024Prices'!D59-'Table1-2014Prices'!E45 -> 4
...

Sheet Table1-2024Prices
A1: Tables on this worksheet show model results with 2024 energy prices
A3: Table 1. Cumulative loss of hydropeaking value ($ million) per number of days of steady release in 2018 with 0.83 MAF release volume, H1000 (offset release), and market prices of $5/MWh above 2024 contract prices. Losses are calculated relative to zero steady low-flow days (hydropeaking). Rows highlighted in blue indicate percentage losses.
C5: Month | D5: Value at zero days of steady low releases | E5: Number of days of steady low reservoir releases
E6: 4 | F6: 6 | G6: 8 | H6: 10 | I6: 15 | J6: 20 | K6: 25 | L6: 30 | M6: 31 | R6: Value at zero days of steady low releases | S6: Number of days of steady low reservoir releases | AI6: Paste the Market Model Fstore values from .gdx file
C7: March | D7: 17.85 | E7: 0.48 | F7: 0.55 | G7: 0.61 | H7: 0.78 | I7: 1.16 | J7: 1.47 | K7: 1.72 | L7: - | M7: 1.98 | S7: 4 | T7: 6 | U7: 8 | V7: 10 | W7: 15 | X7: 20 | Y7: 25 | Z7: 30/31 | AK7: V1 | AL7: V2 | AM7: V3
E8: 0.027 | F8: 0.031 | G8: 0.034 | H8: 0.044 | I8: 0.065 | J8: 0.082 | K8: 0.096 | L8: - | M8: 0.111 | Q8: =AI10 -> PriceScen1 | R8: =AL9/10^6 -> 34.359425 | S8: =($AL$9-AL12)/10^6 -> 0.89731596 | T8: =($AL$9-AL13)/10^6 -> 0.99149055 | U8: =($AL$9-AL14)/10^6 -> 1.0937919 | V8: =($AL$9-AL16)/10^6 -> 1.4644027 | W8: =($AL$9-AL18)/10^6 -> 2.2571215 | X8: =($AL$9-AL19)/10^6 -> 2.8819381 | Y8: =($AL$9-AL20)/10^6 -> 3.4031132 | Z8: =(AL9-AL21)/10^6 -> 3.9387896 | AK8: H4 | AL8: H4 | AM8: H4
C9: April | D9: 17.44 | E9: 0.44 | F9: 0.52 | G9: 0.6 | H9: 0.79 | I9: 1.16 | J9: 1.42 | K9: 1.64 | L9: 1.84 | M9: - | AI9: PriceScen1 | AJ9: case1 | AK9: 29713166 | AL9: 34359425 | AM9: 39021529
E10: 0.025 | F10: 0.03 | G10: 0.034 | H10: 0.045 | I10: 0.067 | J10: 0.081 | K10: 0.094 | L10: 0.106 | M10: - | AI10: PriceScen1 | AJ10: case2 | AK10: 29177821 | AL10: 33513158 | AM10: 38122046
C11: May | D11: 15.57 | E11: 0.71 | F11: 0.8 | G11: 0.87 | H11: 1.07 | I11: 1.51 | J11: 1.87 | K11: 2.11 | L11: - | M11: 2.39 | AI11: PriceScen1 | AJ11: case3 | AK11: 29169256 | AL11: 33495297 | AM11: 38119840
E12: 0.046 | F12: 0.051 | G12: 0.056 | H12: 0.069 | I12: 0.097 | J12: 0.12 | K12: 0.136 | L12: - | M12: 0.154 | AI12: PriceScen1 | AJ12: case4 | AK12: 29152936 | AL12: 33462109 | AM12: 38117155
C13: June | D13: 19.58 | E13: 0.51 | F13: 0.59 | G13: 0.68 | H13: 0.9 | I13: 1.32 | J13: 1.62 | K13: 1.87 | L13: 2.09 | M13: - | AI13: PriceScen1 | AJ13: case5 | AK13: 29092805 | AL13: 33367935 | AM13: 38031483
E14: 0.026 | F14: 0.03 | G14: 0.035 | H14: 0.046 | I14: 0.067 | J14: 0.083 | K14: 0.096 | L14: 0.107 | M14: - | AI14: PriceScen1 | AJ14: case6 | AK14: 29034516 | AL14: 33265634 | AM14: 37942629
C15: July | D15: 28.9 | E15: 0.82 | F15: 0.93 | G15: 1.02 | H15: 1.29 | I15: 1.91 | J15: 2.39 | K15: 2.8 | L15: - | M15: 3.22 | AI15: PriceScen1 | AJ15: case7 | AK15: 28876410 | AL15: 33066665 | AM15: 37774263
E16: 0.028 | F16: 0.032 | G16: 0.035 | H16: 0.045 | I16: 0.066 | J16: 0.083 | K16: 0.097 | L16: - | M16: 0.111 | AI16: PriceScen1 | AJ16: case8 | AK16: 28718304 | AL16: 32895023 | AM16: 37605897
C17: August | D17: 34.36 | E17: 0.89 | F17: 0.99 | G17: 1.09 | H17: 1.46 | I17: 2.25 | J17: 2.88 | K17: 3.4 | L17: - | M17: 3.94 | AI17: PriceScen1 | AJ17: case9 | AK17: 28402092 | AL17: 32551526 | AM17: 37269166
E18: 0.026 | F18: 0.029 | G18: 0.032 | H18: 0.042 | I18: 0.065 | J18: 0.084 | K18: 0.099 | L18: - | M18: 0.115 | AI18: PriceScen1 | AJ18: case10 | AK18: 28010958 | AL18: 32102304 | AM18: 36896217
C19: September | D19: 28.62 | E19: 0.65 | F19: 0.74 | G19: 0.82 | H19: 1.17 | I19: 1.84 | J19: 2.27 | K19: 2.65 | L19: 2.98 | M19: - | AI19: PriceScen1 | AJ19: case11 | AK19: 27462149 | AL19: 31477487 | AM19: 36373098
E20: 0.023 | F20: 0.026 | G20: 0.029 | H20: 0.041 | I20: 0.064 | J20: 0.079 | K20: 0.093 | L20: 0.104 | M20: - | AI20: PriceScen1 | AJ20: case12 | AK20: 26986497 | AL20: 30956312 | AM20: 35928509
C21: October | D21: 24.72 | E21: 0.63 | F21: 0.72 | G21: 0.8 | H21: 1.02 | I21: 1.55 | J21: 1.96 | K21: 2.3 | L21: - | M21: 2.66 | AI21: PriceScen1 | AJ21: case13 | AK21: 26476397 | AL21: 30420636 | AM21: 35462996
E22: 0.025 | F22: 0.029 | G22: 0.032 | H22: 0.041 | I22: 0.063 | J22: 0.079 | K22: 0.093 | L22: - | M22: 0.108 | AI22: PriceScen2 | AJ22: case1 | AK22: 29713166 | AL22: 34359425 | AM22: 39021529
AI23: PriceScen2 | AJ23: case2 | AK23: 29286102 | AL23: 33561448 | AM23: 38246871
AI24: PriceScen2 | AJ24: case3 | AK24: 29277537 | AL24: 33543586 | AM24: 38244665
AI25: PriceScen2 | AJ25: case4 | AK25: 29261217 | AL25: 33510399 | AM25: 38241981
AI26: PriceScen2 | AJ26: case5 | AK26: 29201086 | AL26: 33416224 | AM26: 38156308
AI27: PriceScen2 | AJ27: case6 | AK27: 29142797 | AL27: 33313923 | AM27: 38067454
AI28: PriceScen2 | AJ28: case7 | AK28: 28984691 | AL28: 33114954 | AM28: 37899088
AI29: PriceScen2 | AJ29: case8 | AK29: 28826585 | AL29: 32943312 | AM29: 37730723
AI30: PriceScen2 | AJ30: case9 | AK30: 28510373 | AL30: 32599816 | AM30: 37393991
AI31: PriceScen2 | AJ31: case10 | AK31: 28119239 | AL31: 32150593 | AM31: 37021043
AI32: PriceScen2 | AJ32: case11 | AK32: 27570430 | AL32: 31525777 | AM32: 36497923
AI33: PriceScen2 | AJ33: case12 | AK33: 27094778 | AL33: 31004602 | AM33: 36053334
AI34: PriceScen2 | AJ34: case13 | AK34: 26584678 | AL34: 30468925 | AM34: 35587821
A37: Table 1 with Percentage rows deleted | N37: Sorted by Value
C39: Number of Days of Steady Low Releases | N39: 0
B40: Month | C40: 0 | D40: =E6 -> 4 | E40: =F6 -> 6 | F40: =G6 -> 8 | G40: =H6 -> 10 | H40: =I6 -> 15 | I40: =J6 -> 20 | J40: =K6 -> 25 | K40: =L6 -> 30 | L40: =M6 -> 31 | N40: Month | O40: Zero Days | Q40: Month | R40: 4 | T40: Month | U40: 6 | W40: Month | X40: 8 | Z40: Month | AA40: 10 | AC40: Month | AD40: 15 | AF40: Month | AG40: 20 | AI40: Month | AJ40: 25 | AL40: Month | AM40: 30 | AO40: Month | AP40: 31
B41: =C7 -> March | C41: =D7 -> 17.85 | D41: =E7 -> 0.48 | E41: =F7 -> 0.55 | F41: =G7 -> 0.61 | G41: =H7 -> 0.78 | H41: =I7 -> 1.16 | I41: =J7 -> 1.47 | ... L41: =M7 -> 1.98 | N41: May | O41: 15.57 | Q41: April | R41: 0.44 | T41: April | U41: 0.52 | W41: April | X41: 0.6 | Z41: March | AA41: 0.78 | AC41: March | AD41: 1.16 | AF41: April | AG41: 1.42 | AI41: April | AJ41: 1.64 | AL41: April | AM41: 1.84 | AO41: March | AP41: 1.98
B42: =C9 -> April | C42: =D9 -> 17.44 | D42: =E9 -> 0.44 | E42: =F9 -> 0.52 | F42: =G9 -> 0.6 | G42: =H9 -> 0.79 | H42: =I9 -> 1.16 | I42: =J9 -> 1.42 | ... L42: =M9 -> - | N42: April | O42: 17.44 | Q42: March | R42: 0.48 | T42: March | U42: 0.55 | W42: March | X42: 0.61 | Z42: April | AA42: 0.79 | AC42: April | AD42: 1.16 | AF42: March | AG42: 1.47 | AI42: March | AJ42: 1.72 | AL42: June | AM42: 2.09 | AO42: May | AP42: 2.39
B43: =C11 -> May | C43: =D11 -> 15.57 | D43: =E11 -> 0.71 | E43: =F11 -> 0.8 | F43: =G11 -> 0.87 | G43: =H11 -> 1.07 | H43: =I11 -> 1.51 | I43: =J11 -> 1.87 | ... L43: =M11 -> 2.39 | N43: March | O43: 17.85 | Q43: June | R43: 0.51 | T43: June | U43: 0.59 | W43: June | X43: 0.68 | Z43: June | AA43: 0.9 | AC43: June | AD43: 1.32 | AF43: June | AG43: 1.62 | AI43: June | AJ43: 1.87 | AL43: September | AM43: 2.98 | AO43: October | AP43: 2.66
B44: =C13 -> June | C44: =D13 -> 19.58 | D44: =E13 -> 0.51 | E44: =F13 -> 0.59 | F44: =G13 -> 0.68 | G44: =H13 -> 0.9 | H44: =I13 -> 1.32 | I44: =J13 -> 1.62 | ... L44: =M13 -> - | N44: June | O44: 19.58 | Q44: October | R44: 0.63 | T44: October | U44: 0.72 | W44: October | X44: 0.8 | Z44: October | AA44: 1.02 | AC44: May | AD44: 1.51 | AF44: May | AG44: 1.87 | AI44: May | AJ44: 2.11 | AL44: March | AM44: - | AO44: July | AP44: 3.22
B45: =C15 -> July | C45: =D15 -> 28.9 | D45: =E15 -> 0.82 | E45: =F15 -> 0.93 | F45: =G15 -> 1.02 | G45: =H15 -> 1.29 | H45: =I15 -> 1.91 | I45: =J15 -> 2.39 | ... L45: =M15 -> 3.22 | N45: October | O45: 24.72 | Q45: September | R45: 0.65 | T45: September | U45: 0.74 | W45: September | X45: 0.82 | Z45: May | AA45: 1.07 | AC45: October | AD45: 1.55 | AF45: October | AG45: 1.96 | AI45: October | AJ45: 2.3 | AL45: May | AM45: - | AO45: August | AP45: 3.94
...

Sheet Table1-2014Prices
A3: Table S7. Cumulative loss of hydropeaking value ($ million) per number of days of steady release in 2018 with 0.83 MAF release volume, H1000 (offset release), and market prices of $5/MWh above 2014 contract prices. Losses are calculated relative to zero steady low-flow days (hydropeaking). Rows highlighted in blue indicate percentage losses.
B5: Month | C5: Value at zero steady days | D5: Number of steady low flow days per month
D6: 4 | E6: 6 | F6: 8 | G6: 10 | H6: 15 | I6: 20 | J6: 25 | K6: 30 | L6: 31 | AJ6: Paste the Market Model Fstore values from .gdx file
B7: March | C7: 19.9 | D7: 0.34637816 | E7: 0.40374188 | F7: 0.45369014 | G7: 0.63619272 | H7: 1.043335 | I7: 1.3663088 | J7: 1.6362877 | K7: - | L7: 1.91 | S7: Value at zero days of steady low releases | T7: Number of days of steady low reservoir releases | AL7: V1 | AM7: V2 | AN7: V3
D8: =D7/$C$7 -> 0.017405938 | E8: =E7/$C$7 -> 0.020288536 | F8: =F7/$C$7 -> 0.022798499 | G8: =G7/$C$7 -> 0.031969483 | H8: =H7/$C$7 -> 0.052428894 | I8: =I7/$C$7 -> 0.068658734 | J8: =J7/$C$7 -> 0.082225511 | K8: - | L8: =L7/$C$7 -> 0.095979899 | T8: 4 | U8: 6 | V8: 8 | W8: 10 | X8: 15 | Y8: 20 | Z8: 25 | AA8: 30/31 | AL8: H4 | AM8: H4 | AN8: H4
B9: April | C9: 18.2 | D9: 0.19773631 | E9: 0.25955422 | F9: 0.31885698 | G9: 0.50238726 | H9: 0.81872527 | I9: 1.0679244 | J9: 1.2815198 | K9: 1.4713793 | L9: - | R9: =AJ10 -> PriceScen1 | S9: =AM9/10^6 -> 21.822593 | T9: =($AM$9-AM12)/10^6 -> 0.42123256 | U9: =($AM$9-AM13)/10^6 -> 0.48394058 | V9: =($AM$9-AM14)/10^6 -> 0.54874122 | W9: =($AM$9-AM16)/10^6 -> 0.75878671 | X9: =($AM$9-AM18)/10^6 -> 1.2259276 | Y9: =($AM$9-AM19)/10^6 -> 1.5959945 | Z9: =($AM$9-AM20)/10^6 -> 1.9052544 | AA9: =(AM9-AM21)/10^6 -> 2.2237192 | AJ9: PriceScen1 | AK9: case1 | AL9: 18903673 | AM9: 21822593 | AN9: 24818534
D10: =D9/$C$9 -> 0.010864632 | E10: =E9/$C$9 -> 0.014261221 | F10: =F9/$C$9 -> 0.017519614 | G10: =G9/$C$9 -> 0.027603696 | H10: =H9/$C$9 -> 0.044984905 | I10: =I9/$C$9 -> 0.058677167 | J10: =J9/$C$9 -> 0.070413176 | K10: =K9/$C$9 -> 0.080845017 | L10: - | R10: =AJ22 -> PriceScen2 | S10: =AM22/10^6 -> 21.822593 | T10: =($AM$22-AM25)/10^6 -> 0.37294326 | U10: =($AM$22-AM26)/10^6 -> 0.43565128 | V10: =($AM$22-AM27)/10^6 -> 0.50045192 | W10: =($AM$22-AM29)/10^6 -> 0.71049741 | X10: =($AM$22-AM31)/10^6 -> 1.1776383 | Y10: =($AM$22-AM32)/10^6 -> 1.5477052 | Z10: =($AM$22-AM33)/10^6 -> 1.8569651 | AA10: =(AM22-AM34)/10^6 -> 2.1754299 | AJ10: PriceScen1 | AK10: case2 | AL10: 18654377 | AM10: 21409931 | AN10: 24389970
B11: May | C11: 18.4 | D11: 0.45298109 | E11: 0.50521009 | F11: 0.56239228 | G11: 0.78202913 | H11: 1.2296985 | I11: 1.5802121 | J11: 1.8729305 | K11: - | L11: 2.17 | AJ11: PriceScen1 | AK11: case3 | AL11: 18653502 | AM11: 21406405 | AN11: 24394131
D12: =D11/$C$11 -> 0.024618538 | E12: =E11/$C$11 -> 0.02745707 | F12: =F11/$C$11 -> 0.030564798 | G12: =G11/$C$11 -> 0.042501583 | H12: =H11/$C$11 -> 0.066831441 | I12: =I11/$C$11 -> 0.085881092 | J12: =J11/$C$11 -> 0.1017897 | K12: - | L12: =L11/$C$11 -> 0.11793478 | AJ12: PriceScen1 | AK12: case4 | AL12: 18651557 | AM12: 21401360 | AN12: 24403376
B13: June | C13: 20.1 | D13: 0.30703678 | E13: 0.37092242 | F13: 0.43091936 | G13: 0.67633848 | H13: 1.158222 | I13: 1.4696818 | J13: 1.7346031 | K13: 1.9701551 | L13: - | AJ13: PriceScen1 | AK13: case5 | AL13: 18616401 | AM13: 21338652 | AN13: 24347409
D14: =D13/$C$13 -> 0.015275462 | E14: =E13/$C$13 -> 0.018453852 | F14: =F13/$C$13 -> 0.021438774 | G14: =G13/$C$13 -> 0.033648681 | H14: =H13/$C$13 -> 0.057622983 | I14: =I13/$C$13 -> 0.073118499 | J14: =J13/$C$13 -> 0.086298664 | K14: =K13/$C$13 -> 0.098017667 | L14: - | AJ14: PriceScen1 | AK14: case6 | AL14: 18581874 | AM14: 21273852 | AN14: 24288451
B15: July | C15: 25.3 | D15: 0.69917827 | E15: 0.77039248 | F15: 0.84801718 | G15: 1.158 | H15: 1.8384634 | I15: 2.3482818 | J15: 2.7739041 | K15: - | L15: 3.21 | AJ15: PriceScen1 | AK15: case7 | AL15: 18484223 | AM15: 21166766 | AN15: 24184412
D16: =D15/$C$15 -> 0.027635505 | E16: =E15/$C$15 -> 0.030450295 | F16: =F15/$C$15 -> 0.033518466 | G16: =G15/$C$15 -> 0.045770753 | H16: =H15/$C$15 -> 0.072666538 | I16: =I15/$C$15 -> 0.092817462 | J16: =J15/$C$15 -> 0.10964048 | K16: - | L16: =L15/$C$15 -> 0.12687747 | AJ16: PriceScen1 | AK16: case8 | AL16: 18386571 | AM16: 21063806 | AN16: 24080373
B17: August | C17: 25.5 | D17: 0.62974534 | E17: 0.70193038 | F17: 0.78096119 | G17: 1.0845179 | H17: 1.7032323 | I17: 2.187671 | J17: 2.5922319 | K17: - | L17: 3.01 | AJ17: PriceScen1 | AK17: case9 | AL17: 18208905 | AM17: 20861690 | AN17: 23906253
D18: =D17/$C$17 -> 0.024695896 | E18: =E17/$C$17 -> 0.027526682 | F18: =F17/$C$17 -> 0.030625929 | G18: =G17/$C$17 -> 0.042530115 | H18: =H17/$C$17 -> 0.066793425 | I18: =I17/$C$17 -> 0.085791019 | J18: =J17/$C$17 -> 0.10165615 | K18: - | L18: =L17/$C$17 -> 0.11803922 | AJ18: PriceScen1 | AK18: case10 | AL18: 17978420 | AM18: 20596665 | AN18: 23687442
B19: September | C19: 23.6 | D19: 0.23262458 | E19: 0.30382793 | F19: 0.37371659 | G19: 0.59540606 | H19: 0.94644087 | I19: 1.2515247 | J19: 1.5129664 | K19: 1.7453134 | L19: - | AJ19: PriceScen1 | AK19: case11 | AL19: 17652947 | AM19: 20226599 | AN19: 23377041
D20: =D19/$C$19 -> 0.0098569737 | E20: =E19/$C$19 -> 0.012874065 | F20: =F19/$C$19 -> 0.015835449 | G20: =G19/$C$19 -> 0.02522907 | H20: =H19/$C$19 -> 0.040103427 | I20: =I19/$C$19 -> 0.053030708 | J20: =J19/$C$19 -> 0.064108747 | K20: =K19/$C$19 -> 0.073953958 | L20: - | AJ20: PriceScen1 | AK20: case12 | AL20: 17369229 | AM20: 19917339 | AN20: 23112715
B21: October | C21: 21.8 | D21: 0.42123256 | E21: 0.48394058 | F21: 0.54874122 | G21: 0.75878671 | H21: 1.2259276 | I21: 1.5959945 | J21: 1.9052544 | K21: - | L21: 2.22 | AJ21: PriceScen1 | AK21: case13 | AL21: 17063098 | AM21: 19598874 | AN21: 22835415
D22: =D21/$C$21 -> 0.019322594 | E22: =E21/$C$21 -> 0.022199109 | F22: =F21/$C$21 -> 0.025171616 | G22: =G21/$C$21 -> 0.03480673 | H22: =H21/$C$21 -> 0.056235213 | I22: =I21/$C$21 -> 0.073210756 | J22: =J21/$C$21 -> 0.087396989 | K22: - | L22: =L21/$C$21 -> 0.10183486 | AJ22: PriceScen2 | AK22: case1 | AL22: 18903673 | AM22: 21822593 | AN22: 24818534
AJ23: PriceScen2 | AK23: case2 | AL23: 18762658 | AM23: 21458220 | AN23: 24514796
AJ24: PriceScen2 | AK24: case3 | AL24: 18761783 | AM24: 21454694 | AN24: 24518956
A25: Table 1 with Percentage rows deleted | AJ25: PriceScen2 | AK25: case4 | AL25: 18759838 | AM25: 21449650 | AN25: 24528202
AJ26: PriceScen2 | AK26: case5 | AL26: 18724682 | AM26: 21386942 | AN26: 24472234
C27: Number of Days of Steady Low Releases | AJ27: PriceScen2 | AK27: case6 | AL27: 18690155 | AM27: 21322141 | AN27: 24413276
B28: Month | C28: 0 | D28: =D6 -> 4 | E28: =E6 -> 6 | F28: =F6 -> 8 | G28: =G6 -> 10 | H28: =H6 -> 15 | I28: =I6 -> 20 | J28: =J6 -> 25 | K28: =K6 -> 30 | L28: =L6 -> 31 | AJ28: PriceScen2 | AK28: case7 | AL28: 18592503 | AM28: 21215055 | AN28: 24309237
B29: =B7 -> March | C29: =C7 -> 19.9 | D29: =D7 -> 0.34637816 | E29: =E7 -> 0.40374188 | F29: =F7 -> 0.45369014 | G29: =G7 -> 0.63619272 | H29: =H7 -> 1.043335 | I29: =I7 -> 1.3663088 | ... L29: =L7 -> 1.91 | AJ29: PriceScen2 | AK29: case8 | AL29: 18494852 | AM29: 21112096 | AN29: 24205198
B30: =B9 -> April | C30: =C9 -> 18.2 | D30: =D9 -> 0.19773631 | E30: =E9 -> 0.25955422 | F30: =F9 -> 0.31885698 | G30: =G9 -> 0.50238726 | H30: =H9 -> 0.81872527 | I30: =I9 -> 1.0679244 | ... L30: =L9 -> - | AJ30: PriceScen2 | AK30: case9 | AL30: 18317186 | AM30: 20909980 | AN30: 24031079
B31: =B11 -> May | C31: =C11 -> 18.4 | D31: =D11 -> 0.45298109 | E31: =E11 -> 0.50521009 | F31: =F11 -> 0.56239228 | G31: =G11 -> 0.78202913 | H31: =H11 -> 1.2296985 | I31: =I11 -> 1.5802121 | ... L31: =L11 -> 2.17 | AJ31: PriceScen2 | AK31: case10 | AL31: 18086701 | AM31: 20644955 | AN31: 23812267
B32: =B13 -> June | C32: =C13 -> 20.1 | D32: =D13 -> 0.30703678 | E32: =E13 -> 0.37092242 | F32: =F13 -> 0.43091936 | G32: =G13 -> 0.67633848 | H32: =H13 -> 1.158222 | I32: =I13 -> 1.4696818 | ... L32: =L13 -> - | AJ32: PriceScen2 | AK32: case11 | AL32: 17761228 | AM32: 20274888 | AN32: 23501867
B33: =B15 -> July | C33: =C15 -> 25.3 | D33: =D15 -> 0.69917827 | E33: =E15 -> 0.77039248 | F33: =F15 -> 0.84801718 | G33: =G15 -> 1.158 | H33: =H15 -> 1.8384634 | I33: =I15 -> 2.3482818 | ... L33: =L15 -> 3.21 | AJ33: PriceScen2 | AK33: case12 | AL33: 17477510 | AM33: 19965628 | AN33: 23237540
B34: =B17 -> August | C34: =C17 -> 25.5 | D34: =D17 -> 0.62974534 | E34: =E17 -> 0.70193038 | F34: =F17 -> 0.78096119 | G34: =G17 -> 1.0845179 | H34: =H17 -> 1.7032323 | I34: =I17 -> 2.187671 | ... L34: =L17 -> 3.01 | AJ34: PriceScen2 | AK34: case13 | AL34: 17171379 | AM34: 19647163 | AN34: 22960240
B35: =B19 -> September | C35: =C19 -> 23.6 | D35: =D19 -> 0.23262458 | E35: =E19 -> 0.30382793 | F35: =F19 -> 0.37371659 | G35: =G19 -> 0.59540606 | H35: =H19 -> 0.94644087 | I35: =I19 -> 1.2515247 | ... L35: =L19 -> -
B36: =B21 -> October | C36: =C21 -> 21.8 | D36: =D21 -> 0.42123256 | E36: =E21 -> 0.48394058 | F36: =F21 -> 0.54874122 | G36: =G21 -> 0.75878671 | H36: =H21 -> 1.2259276 | I36: =I21 -> 1.5959945 | ... L36: =L21 -> 2.22
A39: Change in hydropeaking value ($1000) per additional day of steady low reservoir release added in 2018 with 0.83 MAF release volume, H1000 (offset release), and contract energy prices. Positive values show an increase; negative values a decrease.
B41: Month | C41: 0 and 4 steady low flow days | D41: 4 to 8 steady low flow days | E41: Above 8 steady low flow days
B42: March | C42: 20 | D42: -0.6 | E42: -30
B43: April | C43: 23 | D43: -1.2 | E43: -43
B44: May | C44: 30 | D44: -1 | E44: -44
B45: June | C45: 37 | D45: -1.5 | E45: -54
B46: July | C46: 48 | D46: -1.6 | E46: -70
...
